Traceback (most recent call last):
  File "C:\Users\ntk00\anaconda3\Lib\site-packages\jupyter_cache\executors\utils.py", line 58, in single_nb_execution
    executenb(
  File "C:\Users\ntk00\anaconda3\Lib\site-packages\nbclient\client.py", line 1305, in execute
    return NotebookClient(nb=nb, resources=resources, km=km, **kwargs).execute()
           ^^^^^^^^^^^^^^^^^^^^^^^^^^^^^^^^^^^^^^^^^^^^^^^^^^^^^^^^^^^^^^^^^^^^^
  File "C:\Users\ntk00\anaconda3\Lib\site-packages\jupyter_core\utils\__init__.py", line 173, in wrapped
    return loop.run_until_complete(inner)
           ^^^^^^^^^^^^^^^^^^^^^^^^^^^^^^
  File "C:\Users\ntk00\anaconda3\Lib\asyncio\base_events.py", line 653, in run_until_complete
    return future.result()
           ^^^^^^^^^^^^^^^
  File "C:\Users\ntk00\anaconda3\Lib\site-packages\nbclient\client.py", line 705, in async_execute
    await self.async_execute_cell(
  File "C:\Users\ntk00\anaconda3\Lib\site-packages\nbclient\client.py", line 1058, in async_execute_cell
    await self._check_raise_for_error(cell, cell_index, exec_reply)
  File "C:\Users\ntk00\anaconda3\Lib\site-packages\nbclient\client.py", line 914, in _check_raise_for_error
    raise CellExecutionError.from_cell_and_msg(cell, exec_reply_content)
nbclient.exceptions.CellExecutionError: An error occurred while executing the following cell:
------------------
import numpy as np
import matplotlib.pyplot as plt 
import warnings 
warnings.simplefilter("ignore")
import FoKL 

np.random.seed(20)

# Generate data 
x = np.linspace(0, 10, 1000)
y = 3 * x**2 - x + 5 + np.random.normal(loc = 0,scale=3, size=1000)

# Define the normal probability density function (PDF)
def normal_pdf(x, mean, std):
    return (1 / (std * np.sqrt(2 * np.pi))) * np.exp(-(x - mean)**2 / (2 * std**2))

# Define the quadratic model
def model(x, a, b, c):
    return a * x**2 + b * x + c

plt.title('Sample data for ' + r'$y=3x^2-x+5$')
plt.scatter(x,y)
plt.grid()

------------------


[1;31m---------------------------------------------------------------------------[0m
[1;31mModuleNotFoundError[0m                       Traceback (most recent call last)
Cell [1;32mIn[1], line 5[0m
[0;32m      3[0m [38;5;28;01mimport[39;00m [38;5;21;01mwarnings[39;00m 
[0;32m      4[0m warnings[38;5;241m.[39msimplefilter([38;5;124m"[39m[38;5;124mignore[39m[38;5;124m"[39m)
[1;32m----> 5[0m [38;5;28;01mimport[39;00m [38;5;21;01mFoKL[39;00m 
[0;32m      7[0m np[38;5;241m.[39mrandom[38;5;241m.[39mseed([38;5;241m20[39m)
[0;32m      9[0m [38;5;66;03m# Generate data [39;00m

[1;31mModuleNotFoundError[0m: No module named 'FoKL'

